[2022-06-17 20:16:07,328] {taskinstance.py:1159} INFO - Dependencies all met for <TaskInstance: coffee_lake_scrapers-v1.upload_imgs manual__2022-06-17T20:15:31.863976+00:00 [queued]>
[2022-06-17 20:16:07,338] {taskinstance.py:1159} INFO - Dependencies all met for <TaskInstance: coffee_lake_scrapers-v1.upload_imgs manual__2022-06-17T20:15:31.863976+00:00 [queued]>
[2022-06-17 20:16:07,338] {taskinstance.py:1356} INFO - 
--------------------------------------------------------------------------------
[2022-06-17 20:16:07,339] {taskinstance.py:1357} INFO - Starting attempt 1 of 1
[2022-06-17 20:16:07,339] {taskinstance.py:1358} INFO - 
--------------------------------------------------------------------------------
[2022-06-17 20:16:07,351] {taskinstance.py:1377} INFO - Executing <Task(_PythonDecoratedOperator): upload_imgs> on 2022-06-17 20:15:31.863976+00:00
[2022-06-17 20:16:07,356] {standard_task_runner.py:52} INFO - Started process 1283 to run task
[2022-06-17 20:16:07,358] {standard_task_runner.py:79} INFO - Running: ['***', 'tasks', 'run', 'coffee_lake_scrapers-v1', 'upload_imgs', 'manual__2022-06-17T20:15:31.863976+00:00', '--job-id', '349', '--raw', '--subdir', 'DAGS_FOLDER/scraper_dag.py', '--cfg-path', '/tmp/tmphxjykydc', '--error-file', '/tmp/tmptnnpdl5w']
[2022-06-17 20:16:07,359] {standard_task_runner.py:80} INFO - Job 349: Subtask upload_imgs
[2022-06-17 20:16:07,402] {task_command.py:370} INFO - Running <TaskInstance: coffee_lake_scrapers-v1.upload_imgs manual__2022-06-17T20:15:31.863976+00:00 [running]> on host 5a879d076420
[2022-06-17 20:16:07,457] {taskinstance.py:1571} INFO - Exporting the following env vars:
AIRFLOW_CTX_DAG_OWNER=***
AIRFLOW_CTX_DAG_ID=coffee_lake_scrapers-v1
AIRFLOW_CTX_TASK_ID=upload_imgs
AIRFLOW_CTX_EXECUTION_DATE=2022-06-17T20:15:31.863976+00:00
AIRFLOW_CTX_TRY_NUMBER=1
AIRFLOW_CTX_DAG_RUN_ID=manual__2022-06-17T20:15:31.863976+00:00
[2022-06-17 20:16:07,459] {taskinstance.py:1889} ERROR - Task failed with exception
Traceback (most recent call last):
  File "/home/airflow/.local/lib/python3.7/site-packages/airflow/decorators/base.py", line 179, in execute
    return_value = super().execute(context)
  File "/home/airflow/.local/lib/python3.7/site-packages/airflow/operators/python.py", line 171, in execute
    return_value = self.execute_callable()
  File "/home/airflow/.local/lib/python3.7/site-packages/airflow/operators/python.py", line 189, in execute_callable
    return self.python_callable(*self.op_args, **self.op_kwargs)
  File "/opt/airflow/dags/scraper_dag.py", line 169, in upload_imgs
    upload_img_to_gcs(img=outfile, uploaded_filename=outfile)
  File "/opt/airflow/dags/scraper_dag.py", line 198, in upload_img_to_gcs
    client = storage.Client.from_service_account_json(json_credentials_path='/keys/gcp_personal.json')
  File "/home/airflow/.local/lib/python3.7/site-packages/google/cloud/client/__init__.py", line 106, in from_service_account_json
    with io.open(json_credentials_path, "r", encoding="utf-8") as json_fi:
FileNotFoundError: [Errno 2] No such file or directory: '/keys/gcp_personal.json'
[2022-06-17 20:16:07,469] {taskinstance.py:1400} INFO - Marking task as FAILED. dag_id=coffee_lake_scrapers-v1, task_id=upload_imgs, execution_date=20220617T201531, start_date=20220617T201607, end_date=20220617T201607
[2022-06-17 20:16:07,478] {standard_task_runner.py:97} ERROR - Failed to execute job 349 for task upload_imgs ([Errno 2] No such file or directory: '/keys/gcp_personal.json'; 1283)
[2022-06-17 20:16:07,490] {local_task_job.py:156} INFO - Task exited with return code 1
[2022-06-17 20:16:07,514] {local_task_job.py:273} INFO - 0 downstream tasks scheduled from follow-on schedule check
